<?xml version="1.0" ?>
<!-- =================================================================================== -->
<!-- |    This document was autogenerated by xacro from spot.urdf.xacro                | -->
<!-- |    EDITING THIS FILE BY HAND IS NOT RECOMMENDED                                 | -->
<!-- =================================================================================== -->
<robot name="spot">
  <link name="body">
    <visual>
      <geometry>
        <mesh filename="package://spot_description/meshes/base/visual/body.obj"/>
      </geometry>
    </visual>
    <collision>
      <geometry>
        <mesh filename="package://spot_description/meshes/base/collision/body_collision.obj"/>
      </geometry>
    </collision>
  </link>
  <link name="base_link">
    <inertial>
      <origin rpy="0.0 0.0 0.0" xyz="0.006394396536052227 -9.812158532440662e-05 0.0009113792330026627"/>
      <mass value="32.86"/>
      <inertia ixx="0.13143999874591827" ixy="0.0" ixz="0.0" iyy="0.13143999874591827" iyz="0.0" izz="0.13143999874591827"/>
    </inertial>
  </link>
  <joint name="base_link_joint" type="fixed">
    <origin rpy="0 0 0" xyz="0 0 0"/>
    <parent link="body"/>
    <child link="base_link"/>
  </joint>
  <link name="front_rail">
    <inertial>
      <origin rpy="0. 0. 0." xyz="0. 0. 0."/>
      <mass value="1.0e-6"/>
      <inertia ixx="1.0e-9" ixy="0.0" ixz="0.0" iyy="1.0e-9" iyz="0.0" izz="1.0e-9"/>
    </inertial>
  </link>
  <joint name="front_rail_joint" type="fixed">
    <origin rpy="0 0 0" xyz="0.223 0 0.0805"/>
    <parent link="body"/>
    <child link="front_rail"/>
  </joint>
  <link name="rear_rail">
    <inertial>
      <origin rpy="0. 0. 0." xyz="0. 0. 0."/>
      <mass value="1.0e-6"/>
      <inertia ixx="1.0e-9" ixy="0.0" ixz="0.0" iyy="1.0e-9" iyz="0.0" izz="1.0e-9"/>
    </inertial>
  </link>
  <joint name="rear_rail_joint" type="fixed">
    <origin rpy="0 0 0" xyz="-0.223 0 0.0805"/>
    <parent link="body"/>
    <child link="rear_rail"/>
  </joint>
  <link name="front_left_hip">
    <visual>
      <geometry>
        <mesh filename="package://spot_description/meshes/base/visual/front_left_hip.obj"/>
      </geometry>
    </visual>
    <inertial>
      <origin rpy="-0.716521349312305 0.02956473059648479 0.03655230014702582" xyz="-0.005374345928430557 0.012841847725212574 9.875232353806496e-05"/>
      <mass value="1.68"/>
      <inertia ixx="0.0021147398873455382" ixy="0.0" ixz="0.0" iyy="0.0018129577956607131" iyz="0.0" izz="0.002265435737304666"/>
    </inertial>
  </link>
  <joint name="front_left_hip_x" type="revolute">
    <origin rpy="0 0 0" xyz="0.29785 0.05500 0.00000"/>
    <axis xyz="1 0 0"/>
    <parent link="body"/>
    <child link="front_left_hip"/>
    <limit effort="1000" lower="-0.78539816339744827899" upper="0.78539816339744827899" velocity="1000.00"/>
  </joint>
  <link name="front_left_upper_leg">
    <visual>
      <geometry>
        <mesh filename="package://spot_description/meshes/base/visual/front_left_upper_leg.obj"/>
      </geometry>
    </visual>
    <collision>
      <geometry>
        <mesh filename="package://spot_description/meshes/base/collision/left_upper_leg_collision.obj"/>
      </geometry>
    </collision>
    <inertial>
      <origin rpy="-0.26437828203369795 -0.04853174570753804 0.024046963096353124" xyz="0.005142373498529196 -0.0024323679972440004 -0.12100915610790253"/>
      <mass value="2.34"/>
      <inertia ixx="0.02755964961185679" ixy="0.0" ixz="0.0" iyy="0.027354914287651046" iyz="0.0" izz="0.002848145546743553"/>
    </inertial>
  </link>
  <joint name="front_left_hip_y" type="revolute">
    <origin rpy="0 0 0" xyz="0.0 0.110945 0.0"/>
    <axis xyz="0 1 0"/>
    <parent link="front_left_hip"/>
    <child link="front_left_upper_leg"/>
    <limit effort="1000" lower="-0.89884456477707963539" upper="2.2951079663725435509" velocity="1000.00"/>
  </joint>
  <link name="front_left_lower_leg">
    <visual>
      <geometry>
        <mesh filename="package://spot_description/meshes/base/visual/front_left_lower_leg.obj"/>
      </geometry>
    </visual>
    <collision>
      <geometry>
        <mesh filename="package://spot_description/meshes/base/collision/left_lower_leg_collision.obj"/>
      </geometry>
    </collision>
    <collision>
      <origin rpy="0 0 0" xyz="0.0 0.0 -0.3365"/>
      <geometry>
        <sphere radius="0.036"/>
      </geometry>
    </collision>
    <inertial>
      <origin rpy="-0.007266925694167092 -0.009591807116834161 0.00035255970529224356" xyz="0.00225794012658298 4.607596201822162e-05 -0.1800822913646698"/>
      <mass value="0.35"/>
      <inertia ixx="0.003999022654901177" ixy="0.0" ixz="0.0" iyy="0.0040503157598010785" iyz="0.0" izz="0.0001493402097647426"/>
    </inertial>
  </link>
  <joint name="front_left_knee" type="revolute">
    <origin rpy="0 0 0" xyz="0.025 0.000 -0.3205"/>
    <axis xyz="0 1 0"/>
    <parent link="front_left_upper_leg"/>
    <child link="front_left_lower_leg"/>
    <limit effort="1000" lower="-2.7929" upper="-0.254801" velocity="1000.00"/>
  </joint>
  <link name="front_right_hip">
    <visual>
      <geometry>
        <mesh filename="package://spot_description/meshes/base/visual/front_right_hip.obj"/>
      </geometry>
    </visual>
    <inertial>
      <origin rpy="0.7165213493123055 -0.02956473059648479 0.03655230014702582" xyz="-0.005374345928430557 -0.012841847725212574 -9.875232353806496e-05"/>
      <mass value="1.68"/>
      <inertia ixx="0.0021147398873455382" ixy="0.0" ixz="0.0" iyy="0.0018129577956607131" iyz="0.0" izz="0.002265435737304666"/>
    </inertial>
  </link>
  <joint name="front_right_hip_x" type="revolute">
    <origin rpy="0 0 0" xyz="0.29785 -0.05500 0.00000"/>
    <axis xyz="1 0 0"/>
    <parent link="body"/>
    <child link="front_right_hip"/>
    <limit effort="1000" lower="-0.78539816339744827899" upper="0.78539816339744827899" velocity="1000.00"/>
  </joint>
  <link name="front_right_upper_leg">
    <visual>
      <geometry>
        <mesh filename="package://spot_description/meshes/base/visual/front_right_upper_leg.obj"/>
      </geometry>
    </visual>
    <collision>
      <geometry>
        <mesh filename="package://spot_description/meshes/base/collision/right_upper_leg_collision.obj"/>
      </geometry>
    </collision>
    <inertial>
      <origin rpy="0.2643905306958363 -0.04853174688302708 -0.024046943559834943" xyz="0.005142373498529196 0.0024323677644133568 -0.12100915610790253"/>
      <mass value="2.34"/>
      <inertia ixx="0.02755964678927691" ixy="0.0" ixz="0.0" iyy="0.02735491706466737" iyz="0.0" izz="0.0028481453594764797"/>
    </inertial>
  </link>
  <joint name="front_right_hip_y" type="revolute">
    <origin rpy="0 0 0" xyz="0.0 -0.110945 0.0"/>
    <axis xyz="0 1 0"/>
    <parent link="front_right_hip"/>
    <child link="front_right_upper_leg"/>
    <limit effort="1000" lower="-0.89884456477707963539" upper="2.2951079663725435509" velocity="1000.00"/>
  </joint>
  <link name="front_right_lower_leg">
    <visual>
      <geometry>
        <mesh filename="package://spot_description/meshes/base/visual/front_right_lower_leg.obj"/>
      </geometry>
    </visual>
    <collision>
      <geometry>
        <mesh filename="package://spot_description/meshes/base/collision/right_lower_leg_collision.obj"/>
      </geometry>
    </collision>
    <collision>
      <origin rpy="0 0 0" xyz="0.0 0.0 -0.3365"/>
      <geometry>
        <sphere radius="0.036"/>
      </geometry>
    </collision>
    <inertial>
      <origin rpy="-0.007266925694167092 -0.009591807116834161 0.00035255970529224356" xyz="0.00225794012658298 4.607596201822162e-05 -0.1800822913646698"/>
      <mass value="0.35"/>
      <inertia ixx="0.003999022654901177" ixy="0.0" ixz="0.0" iyy="0.0040503157598010785" iyz="0.0" izz="0.0001493402097647426"/>
    </inertial>
  </link>
  <joint name="front_right_knee" type="revolute">
    <origin rpy="0 0 0" xyz="0.025 0.000 -0.3205"/>
    <axis xyz="0 1 0"/>
    <parent link="front_right_upper_leg"/>
    <child link="front_right_lower_leg"/>
    <limit effort="1000" lower="-2.7929" upper="-0.247563" velocity="1000.00"/>
  </joint>
  <link name="rear_left_hip">
    <visual>
      <geometry>
        <mesh filename="package://spot_description/meshes/base/visual/rear_left_hip.obj"/>
      </geometry>
    </visual>
    <inertial>
      <origin rpy="0.7165213493123055 -0.02956473059648479 0.03655230014702582" xyz="-0.005374345928430557 -0.012841847725212574 -9.875232353806496e-05"/>
      <mass value="1.68"/>
      <inertia ixx="0.0021147398873455382" ixy="0.0" ixz="0.0" iyy="0.0018129577956607131" iyz="0.0" izz="0.002265435737304666"/>
    </inertial>
  </link>
  <joint name="rear_left_hip_x" type="revolute">
    <origin rpy="0 0 0" xyz="-0.29785 0.05500 0.00000"/>
    <axis xyz="1 0 0"/>
    <parent link="body"/>
    <child link="rear_left_hip"/>
    <limit effort="1000" lower="-0.78539816339744827899" upper="0.78539816339744827899" velocity="1000.00"/>
  </joint>
  <link name="rear_left_upper_leg">
    <visual>
      <geometry>
        <mesh filename="package://spot_description/meshes/base/visual/rear_left_upper_leg.obj"/>
      </geometry>
    </visual>
    <collision>
      <geometry>
        <mesh filename="package://spot_description/meshes/base/collision/left_upper_leg_collision.obj"/>
      </geometry>
    </collision>
    <inertial>
      <origin rpy="-0.26437828203369795 -0.04853174570753804 0.024046963096353124" xyz="0.005142373498529196 -0.0024323679972440004 -0.12100915610790253"/>
      <mass value="2.34"/>
      <inertia ixx="0.02755964961185679" ixy="0.0" ixz="0.0" iyy="0.027354914287651046" iyz="0.0" izz="0.002848145546743553"/>
    </inertial>
  </link>
  <joint name="rear_left_hip_y" type="revolute">
    <origin rpy="0 0 0" xyz="0.0 0.110945 0.0"/>
    <axis xyz="0 1 0"/>
    <parent link="rear_left_hip"/>
    <child link="rear_left_upper_leg"/>
    <limit effort="1000" lower="-0.89884456477707963539" upper="2.2951079663725435509" velocity="1000.00"/>
  </joint>
  <link name="rear_left_lower_leg">
    <visual>
      <geometry>
        <mesh filename="package://spot_description/meshes/base/visual/rear_left_lower_leg.obj"/>
      </geometry>
    </visual>
    <collision>
      <geometry>
        <mesh filename="package://spot_description/meshes/base/collision/left_lower_leg_collision.obj"/>
      </geometry>
    </collision>
    <collision>
      <origin rpy="0 0 0" xyz="0.0 0.0 -0.3365"/>
      <geometry>
        <sphere radius="0.036"/>
      </geometry>
    </collision>
    <inertial>
      <origin rpy="-0.007266925694167092 -0.009591807116834161 0.00035255970529224356" xyz="0.00225794012658298 4.607596201822162e-05 -0.1800822913646698"/>
      <mass value="0.35"/>
      <inertia ixx="0.003999022654901177" ixy="0.0" ixz="0.0" iyy="0.0040503157598010785" iyz="0.0" izz="0.0001493402097647426"/>
    </inertial>
  </link>
  <joint name="rear_left_knee" type="revolute">
    <origin rpy="0 0 0" xyz="0.025 0.000 -0.3205"/>
    <axis xyz="0 1 0"/>
    <parent link="rear_left_upper_leg"/>
    <child link="rear_left_lower_leg"/>
    <limit effort="1000" lower="-2.7929" upper="-0.267153" velocity="1000.00"/>
  </joint>
  <link name="rear_right_hip">
    <visual>
      <geometry>
        <mesh filename="package://spot_description/meshes/base/visual/rear_right_hip.obj"/>
      </geometry>
    </visual>
    <inertial>
      <origin rpy="0.7165213493123055 -0.02956473059648479 0.03655230014702582" xyz="-0.005374345928430557 -0.012841847725212574 -9.875232353806496e-05"/>
      <mass value="1.68"/>
      <inertia ixx="0.0021147398873455382" ixy="0.0" ixz="0.0" iyy="0.0018129577956607131" iyz="0.0" izz="0.002265435737304666"/>
    </inertial>
  </link>
  <joint name="rear_right_hip_x" type="revolute">
    <origin rpy="0 0 0" xyz="-0.29785 -0.05500 0.00000"/>
    <axis xyz="1 0 0"/>
    <parent link="body"/>
    <child link="rear_right_hip"/>
    <limit effort="1000" lower="-0.78539816339744827899" upper="0.78539816339744827899" velocity="1000.00"/>
  </joint>
  <link name="rear_right_upper_leg">
    <visual>
      <geometry>
        <mesh filename="package://spot_description/meshes/base/visual/rear_right_upper_leg.obj"/>
      </geometry>
    </visual>
    <collision>
      <geometry>
        <mesh filename="package://spot_description/meshes/base/collision/right_upper_leg_collision.obj"/>
      </geometry>
    </collision>
    <inertial>
      <origin rpy="0.2643905306958363 -0.04853174688302708 -0.024046943559834943" xyz="0.005142373498529196 0.0024323677644133568 -0.12100915610790253"/>
      <mass value="2.34"/>
      <inertia ixx="0.02755964678927691" ixy="0.0" ixz="0.0" iyy="0.02735491706466737" iyz="0.0" izz="0.0028481453594764797"/>
    </inertial>
  </link>
  <joint name="rear_right_hip_y" type="revolute">
    <origin rpy="0 0 0" xyz="0.0 -0.110945 0.0"/>
    <axis xyz="0 1 0"/>
    <parent link="rear_right_hip"/>
    <child link="rear_right_upper_leg"/>
    <limit effort="1000" lower="-0.89884456477707963539" upper="2.2951079663725435509" velocity="1000.00"/>
  </joint>
  <link name="rear_right_lower_leg">
    <visual>
      <geometry>
        <mesh filename="package://spot_description/meshes/base/visual/rear_right_lower_leg.obj"/>
      </geometry>
    </visual>
    <collision>
      <geometry>
        <mesh filename="package://spot_description/meshes/base/collision/right_lower_leg_collision.obj"/>
      </geometry>
    </collision>
    <collision>
      <origin rpy="0 0 0" xyz="0.0 0.0 -0.3365"/>
      <geometry>
        <sphere radius="0.036"/>
      </geometry>
    </collision>
    <inertial>
      <origin rpy="-0.007266925694167092 -0.009591807116834161 0.00035255970529224356" xyz="0.00225794012658298 4.607596201822162e-05 -0.1800822913646698"/>
      <mass value="0.35"/>
      <inertia ixx="0.003999022654901177" ixy="0.0" ixz="0.0" iyy="0.0040503157598010785" iyz="0.0" izz="0.0001493402097647426"/>
    </inertial>
  </link>
  <joint name="rear_right_knee" type="revolute">
    <origin rpy="0 0 0" xyz="0.025 0.000 -0.3205"/>
    <axis xyz="0 1 0"/>
    <parent link="rear_right_upper_leg"/>
    <child link="rear_right_lower_leg"/>
    <limit effort="1000" lower="-2.7929" upper="-0.257725" velocity="1000.00"/>
  </joint>
  <!-- This file is a placeholder which is included by default from
       spot.urdf.xacro. If a robot is being customized and requires
       additional URDF, set the SPOT_URDF_EXTRAS environment variable
       to the full path of the file you would like included. -->
  <link name="arm_link_sh0">
    <visual>
      <origin rpy="0 0 0" xyz="0 0 0"/>
      <geometry>
        <mesh filename="package://spot_description/meshes/arm/visual/arm_link_sh0.obj"/>
      </geometry>
      <material name="arm_link_sh0">
        <color rgba="0.2 0.2 0.2 1"/>
      </material>
    </visual>
    <collision>
      <geometry>
        <mesh filename="package://spot_description/meshes/arm/collision/arm_link_sh0_base.obj"/>
      </geometry>
    </collision>
    <collision>
      <geometry>
        <mesh filename="package://spot_description/meshes/arm/collision/arm_link_sh0_left_motor.obj"/>
      </geometry>
    </collision>
    <collision>
      <geometry>
        <mesh filename="package://spot_description/meshes/arm/collision/arm_link_sh0_right_motor.obj"/>
      </geometry>
    </collision>
    <inertial>
      <origin rpy="0.0013490340912847287 -0.15433618253071657 0.0066354181456347305" xyz="-0.012372709810733795 -4.5211403630673885e-05 -0.02103196457028389"/>
      <mass value="2.3364000000000003"/>
      <inertia ixx="0.009014303010689815" ixy="0.0" ixz="0.0" iyy="0.005835102417829581" iyz="0.0" izz="0.00778747846359954"/>
    </inertial>
  </link>
  <joint name="arm_sh0" type="revolute">
    <origin rpy="0 0 0" xyz="0.292 0.0 0.188"/>
    <axis xyz="0 0 1"/>
    <parent link="body"/>
    <child link="arm_link_sh0"/>
    <limit effort="1000" lower="-2.61799387799149441136" upper="3.14159265358979311599" velocity="1000.00"/>
  </joint>
  <link name="arm_link_sh1">
    <visual>
      <origin rpy="0 0 0" xyz="0 0 0"/>
      <geometry>
        <mesh filename="package://spot_description/meshes/arm/visual/arm_link_sh1.obj"/>
      </geometry>
      <material name="arm_link_sh1">
        <color rgba="0.2 0.2 0.2 1"/>
      </material>
    </visual>
    <inertial>
      <origin rpy="0.009910032200701302 -0.5123007314267984 0.002209016500439809" xyz="2.4176391889341176e-05 2.4116111490002368e-06 -1.0059113265015185e-05"/>
      <mass value="0.2596"/>
      <inertia ixx="0.00020292766231464653" ixy="0.0" ixz="0.0" iyy="0.00017078637725384855" iyz="0.0" izz="0.00020384964230406682"/>
    </inertial>
  </link>
  <joint name="arm_sh1" type="revolute">
    <origin rpy="0 0 0" xyz="0.0 0.0 0.0"/>
    <axis xyz="0 1 0"/>
    <parent link="arm_link_sh0"/>
    <child link="arm_link_sh1"/>
    <!-- <limit effort="1000" velocity="1000.00" lower="-0.52359877559829881565"
      upper="3.14159265358979311599"/> -->
    <limit effort="1000" lower="-3.14159265358979311599" upper="0.52359877559829881565" velocity="1000.00"/>
  </joint>
  <link name="arm_link_hr0">
    <visual>
      <origin rpy="0 0 0" xyz="0 0 0"/>
      <geometry>
        <mesh filename="package://spot_description/meshes/arm/visual/arm_link_hr0.obj"/>
      </geometry>
      <material name="arm_link_hr0">
        <color rgba="0.2 0.2 0.2 1"/>
      </material>
    </visual>
    <collision>
      <geometry>
        <mesh filename="package://spot_description/meshes/arm/collision/arm_link_hr0.obj"/>
      </geometry>
    </collision>
    <inertial>
      <origin rpy="-0.01179850657706405 0.0002834144901480151 -0.02372295500868482" xyz="0.17047011852264404 -0.0019251034827902913 4.483893280848861e-05"/>
      <mass value="1e-06"/>
      <inertia ixx="6.312631747339145e-10" ixy="0.0" ixz="0.0" iyy="1.1487063558949979e-08" iyz="0.0" izz="1.161105128440526e-08"/>
    </inertial>
  </link>
  <joint name="arm_hr0" type="fixed">
    <origin rpy="0 0 0" xyz="0.0 0.0 0.0"/>
    <axis xyz="1 0 0"/>
    <parent link="arm_link_sh1"/>
    <child link="arm_link_hr0"/>
    <limit effort="1000" lower="-1e6" upper="1e6" velocity="1000.00"/>
  </joint>
  <link name="arm_link_el0">
    <visual>
      <origin rpy="0 0 0" xyz="0 0 0"/>
      <geometry>
        <mesh filename="package://spot_description/meshes/arm/visual/arm_link_el0.obj"/>
      </geometry>
      <material name="arm_link_el0">
        <color rgba="0.2 0.2 0.2 1"/>
      </material>
    </visual>
    <collision>
      <geometry>
        <mesh filename="package://spot_description/meshes/arm/collision/arm_link_el0.obj"/>
      </geometry>
    </collision>
    <inertial>
      <origin rpy="-0.004185887288594259 -0.6136269547775202 -0.0004619387581783485" xyz="0.0553741455078125 0.00023603376757819206 0.04827198013663292"/>
      <mass value="0.725"/>
      <inertia ixx="0.0008215365829160558" ixy="0.0" ixz="0.0" iyy="0.0020047889807066404" iyz="0.0" izz="0.0019722797759789395"/>
    </inertial>
  </link>
  <joint name="arm_el0" type="revolute">
    <origin rpy="0 0 0" xyz="0.3385 0 0"/>
    <axis xyz="0 1 0"/>
    <parent link="arm_link_hr0"/>
    <child link="arm_link_el0"/>
    <limit effort="1000" lower="0" upper="3.14159265358979311599" velocity="1000.00"/>
  </joint>
  <link name="arm_link_el1">
    <visual>
      <origin rpy="0 0 0" xyz="0 0 0"/>
      <geometry>
        <mesh filename="package://spot_description/meshes/arm/visual/arm_link_el1.obj"/>
      </geometry>
      <material name="arm_link_el1">
        <color rgba="0.2 0.2 0.2 1"/>
      </material>
    </visual>
    <collision>
      <geometry>
        <mesh filename="package://spot_description/meshes/arm/collision/arm_link_el1_main.obj"/>
      </geometry>
    </collision>
    <collision>
      <geometry>
        <mesh filename="package://spot_description/meshes/arm/collision/arm_link_el1_lip.obj"/>
      </geometry>
    </collision>
    <inertial>
      <origin rpy="-0.15027374227250867 -0.0007874585461915551 0.003728225436950172" xyz="-0.1257835328578949 -0.013684478588402271 0.00010157923679798841"/>
      <mass value="0.725"/>
      <inertia ixx="0.0006254807525240598" ixy="0.0" ixz="0.0" iyy="0.004402454711936095" iyz="0.0" izz="0.004515915146038191"/>
    </inertial>
  </link>
  <joint name="arm_el1" type="revolute">
    <origin rpy="0 0 0" xyz="0.40330 0.0 0.0750"/>
    <axis xyz="1 0 0"/>
    <parent link="arm_link_el0"/>
    <child link="arm_link_el1"/>
    <limit effort="1000" lower="-2.79252680319092716487" upper="2.79252680319092716487" velocity="1000.00"/>
  </joint>
  <link name="arm_link_wr0">
    <visual>
      <origin rpy="0 0 0" xyz="0 0 0"/>
      <geometry>
        <mesh filename="package://spot_description/meshes/arm/visual/arm_link_wr0.obj"/>
      </geometry>
      <material name="arm_link_wr0">
        <color rgba="0.2 0.2 0.2 1"/>
      </material>
    </visual>
    <collision>
      <geometry>
        <mesh filename="package://spot_description/meshes/arm/collision/arm_link_wr0.obj"/>
      </geometry>
    </collision>
    <inertial>
      <origin rpy="-0.4951534907966386 0.0033720434077784134 0.020027599337697932" xyz="0.008210677653551102 -0.012051000259816647 3.143483627354726e-05"/>
      <mass value="0.98"/>
      <inertia ixx="0.0009851320696685427" ixy="0.0" ixz="0.0" iyy="0.0008916145765810678" iyz="0.0" izz="0.0012354892751854467"/>
    </inertial>
  </link>
  <joint name="arm_wr0" type="revolute">
    <origin rpy="0 0 0" xyz="0.0 0.0 0.0"/>
    <axis xyz="0 1 0"/>
    <parent link="arm_link_el1"/>
    <child link="arm_link_wr0"/>
    <limit effort="1000" lower="-1.83259571459404613236" upper="1.83259571459404613236" velocity="1000.00"/>
  </joint>
  <link name="arm_link_wr1">
    <visual>
      <origin rpy="0 0 0" xyz="0 0 0"/>
      <geometry>
        <mesh filename="package://spot_description/meshes/arm/visual/arm_link_wr1.obj"/>
      </geometry>
      <material name="arm_link_wr1">
        <color rgba="0.2 0.2 0.2 1"/>
      </material>
    </visual>
    <collision>
      <geometry>
        <mesh filename="package://spot_description/meshes/arm/collision/arm_link_wr1.obj"/>
      </geometry>
    </collision>
    <collision>
      <geometry>
        <mesh filename="package://spot_description/meshes/arm/collision/front_jaw.obj">
          <drake:declare_convex/>
        </mesh>
      </geometry>
      <drake:proximity_properties>
        <drake:compliant_hydroelastic/>
        <drake:hydroelastic_modulus value="1e6"/>
      </drake:proximity_properties>
    </collision>
    <collision>
      <geometry>
        <mesh filename="package://spot_description/meshes/arm/collision/middle_jaw.obj">
          <drake:declare_convex/>
        </mesh>
      </geometry>
      <drake:proximity_properties>
        <drake:compliant_hydroelastic/>
        <drake:hydroelastic_modulus value="1e6"/>
      </drake:proximity_properties>
    </collision>
    <collision>
      <geometry>
        <mesh filename="package://spot_description/meshes/arm/collision/jaw_tooth.obj">
          <drake:declare_convex/>
        </mesh>
      </geometry>
      <drake:proximity_properties>
        <drake:compliant_hydroelastic/>
        <drake:hydroelastic_modulus value="1e6"/>
      </drake:proximity_properties>
    </collision>
    <inertial>
      <origin rpy="0.006393076449033863 0.2928526604761865 -0.022814984050994802" xyz="0.12516802549362183 0.00010137435310753062 -0.013997982256114483"/>
      <mass value="0.785"/>
      <inertia ixx="0.00076741362048185" ixy="0.0" ixz="0.0" iyy="0.0017628124054271809" iyz="0.0" izz="0.0016818105865345951"/>
    </inertial>
  </link>
  <joint name="arm_wr1" type="revolute">
    <origin rpy="0 0 0" xyz="0.0 0.0 0.0"/>
    <axis xyz="1 0 0"/>
    <parent link="arm_link_wr0"/>
    <child link="arm_link_wr1"/>
    <limit effort="1000" lower="-2.87979326579064354163" upper="2.87979326579064354163" velocity="1000.00"/>
  </joint>
  <link name="arm_link_fngr">
    <visual>
      <origin rpy="0 0 0" xyz="0 0 0"/>
      <geometry>
        <mesh filename="package://spot_description/meshes/arm/visual/arm_link_fngr.obj"/>
      </geometry>
      <material name="arm_link_fngr">
        <color rgba="0.2 0.2 0.2 1"/>
      </material>
    </visual>
    <collision>
      <geometry>
        <mesh filename="package://spot_description/meshes/arm/collision/left_hinge.obj"/>
      </geometry>
    </collision>
    <collision>
      <geometry>
        <mesh filename="package://spot_description/meshes/arm/collision/left_finger.obj">
          <drake:declare_convex/>
        </mesh>
      </geometry>
      <drake:proximity_properties>
        <drake:compliant_hydroelastic/>
        <drake:hydroelastic_modulus value="1e6"/>
      </drake:proximity_properties>
    </collision>
    <collision>
      <geometry>
        <mesh filename="package://spot_description/meshes/arm/collision/left_tooth.obj">
          <drake:declare_convex/>
        </mesh>
      </geometry>
      <drake:proximity_properties>
        <drake:compliant_hydroelastic/>
        <drake:hydroelastic_modulus value="1e6"/>
      </drake:proximity_properties>
    </collision>
    <collision>
      <geometry>
        <mesh filename="package://spot_description/meshes/arm/collision/right_hinge.obj"/>
      </geometry>
    </collision>
    <collision>
      <geometry>
        <mesh filename="package://spot_description/meshes/arm/collision/right_finger.obj">
          <drake:declare_convex/>
        </mesh>
      </geometry>
      <drake:proximity_properties>
        <drake:compliant_hydroelastic/>
        <drake:hydroelastic_modulus value="1e6"/>
      </drake:proximity_properties>
    </collision>
    <collision>
      <geometry>
        <mesh filename="package://spot_description/meshes/arm/collision/right_tooth.obj">
          <drake:declare_convex/>
        </mesh>
      </geometry>
      <drake:proximity_properties>
        <drake:compliant_hydroelastic/>
        <drake:hydroelastic_modulus value="1e6"/>
      </drake:proximity_properties>
    </collision>
    <inertial>
      <origin rpy="0.0003416659657240473 0.3751670012784243 -0.004058661249495721" xyz="0.04787873849272728 -0.00020676758140325546 -0.01628788933157921"/>
      <mass value="0.2"/>
      <inertia ixx="0.0001439963634171048" ixy="0.0" ixz="0.0" iyy="0.0003007126997998294" iyz="0.0" izz="0.0003912783268020657"/>
    </inertial>
  </link>
  <joint name="arm_f1x" type="revolute">
    <origin rpy="0 0 0" xyz="0.11745 0 0.014820"/>
    <axis xyz="0.0 1.0 0.0"/>
    <parent link="arm_link_wr1"/>
    <child link="arm_link_fngr"/>
    <limit effort="1000" lower="-1.57" upper="0.0" velocity="1000.00"/>
  </joint>
  <drake:collision_filter_group name="group_front_right_upper_leg">
    <drake:member link="body"/>
    <drake:member link="front_right_upper_leg"/>
    <drake:ignored_collision_filter_group name="group_front_right_upper_leg"/>
  </drake:collision_filter_group>  
  <drake:collision_filter_group name="group_front_left_upper_leg">
    <drake:member link="body"/>
    <drake:member link="front_left_upper_leg"/>
    <drake:ignored_collision_filter_group name="group_front_left_upper_leg"/>
  </drake:collision_filter_group>
  <drake:collision_filter_group name="group_rear_left_upper_leg">
    <drake:member link="body"/>
    <drake:member link="rear_left_upper_leg"/>
    <drake:ignored_collision_filter_group name="group_rear_left_upper_leg"/>
  </drake:collision_filter_group>
  <drake:collision_filter_group name="group_rear_right_upper_leg">
    <drake:member link="body"/>
    <drake:member link="rear_right_upper_leg"/>
    <drake:ignored_collision_filter_group name="group_rear_right_upper_leg"/>
  </drake:collision_filter_group>
   <drake:collision_filter_group name="group_arm_link_sh1">
    <drake:member link="arm_link_sh0"/>
    <drake:member link="arm_link_hr0"/>
    <drake:ignored_collision_filter_group name="group_arm_link_sh1"/>
  </drake:collision_filter_group>
  <transmission type="SimpleTransmission" name="front_left_hip_x_trans">
    <actuator name="front_left_hip_x"/>
    <joint name="front_left_hip_x"/>
  </transmission>
  <transmission type="SimpleTransmission" name="front_left_hip_y_trans">
    <actuator name="front_left_hip_y"/>
    <joint name="front_left_hip_y"/>
  </transmission>
  <transmission type="SimpleTransmission" name="front_left_knee_trans">
    <actuator name="front_left_knee"/>
    <joint name="front_left_knee"/>
  </transmission>
  <transmission type="SimpleTransmission" name="front_right_hip_x_trans">
    <actuator name="front_right_hip_x"/>
    <joint name="front_right_hip_x"/>
  </transmission>
  <transmission type="SimpleTransmission" name="front_right_hip_y_trans">
    <actuator name="front_right_hip_y"/>
    <joint name="front_right_hip_y"/>
  </transmission>
  <transmission type="SimpleTransmission" name="front_right_knee_trans">
    <actuator name="front_right_knee"/>
    <joint name="front_right_knee"/>
  </transmission>
  <transmission type="SimpleTransmission" name="rear_left_hip_x_trans">
    <actuator name="rear_left_hip_x"/>
    <joint name="rear_left_hip_x"/>
  </transmission>
  <transmission type="SimpleTransmission" name="rear_left_hip_y_trans">
    <actuator name="rear_left_hip_y"/>
    <joint name="rear_left_hip_y"/>
  </transmission>
  <transmission type="SimpleTransmission" name="rear_left_knee_trans">
    <actuator name="rear_left_knee"/>
    <joint name="rear_left_knee"/>
  </transmission>
  <transmission type="SimpleTransmission" name="rear_right_hip_x_trans">
    <actuator name="rear_right_hip_x"/>
    <joint name="rear_right_hip_x"/>
  </transmission>
  <transmission type="SimpleTransmission" name="rear_right_hip_y_trans">
    <actuator name="rear_right_hip_y"/>
    <joint name="rear_right_hip_y"/>
  </transmission>
  <transmission type="SimpleTransmission" name="rear_right_knee_trans">
    <actuator name="rear_right_knee"/>
    <joint name="rear_right_knee"/>
  </transmission>
  <transmission type="SimpleTransmission" name="arm_sh0_trans">
    <actuator name="arm_sh0"/>
    <joint name="arm_sh0"/>
  </transmission>
  <transmission type="SimpleTransmission" name="arm_sh1_trans">
    <actuator name="arm_sh1"/>
    <joint name="arm_sh1"/>
  </transmission>
  <transmission type="SimpleTransmission" name="arm_el0_trans">
    <actuator name="arm_el0"/>
    <joint name="arm_el0"/>
  </transmission>
  <transmission type="SimpleTransmission" name="arm_el1_trans">
    <actuator name="arm_el1"/>
    <joint name="arm_el1"/>
  </transmission>
  <transmission type="SimpleTransmission" name="arm_wr0_trans">
    <actuator name="arm_wr0"/>
    <joint name="arm_wr0"/>
  </transmission>
  <transmission type="SimpleTransmission" name="arm_wr1_trans">
    <actuator name="arm_wr1"/>
    <joint name="arm_wr1"/>
  </transmission>
  <transmission type="SimpleTransmission" name="arm_f1x_trans">
    <actuator name="arm_f1x"/>
    <joint name="arm_f1x"/>
  </transmission>
  </robot>
