<?xml version="1.0" ?>
<!-- =================================================================================== -->
<!-- |    This document was autogenerated by xacro from spot.urdf.xacro                | -->
<!-- |    EDITING THIS FILE BY HAND IS NOT RECOMMENDED                                 | -->
<!-- =================================================================================== -->
<robot name="spot">
  <link name="body">
    <visual>
      <geometry>
        <mesh filename="package://spot_description/meshes/base/visual/body.obj"/>
      </geometry>
    </visual>
    <collision>
      <geometry>
        <mesh filename="package://spot_description/meshes/base/collision/body_collision.obj"/>
      </geometry>
    </collision>
  </link>
  <link name="base_link">
    <inertial>
      <origin rpy="0.0 0.0 0.0" xyz="0.006394396536052227 -9.812158532440662e-05 0.0009113792330026627"/>
      <mass value="32.86"/>
      <inertia ixx="0.13143999874591827" ixy="0.0" ixz="0.0" iyy="0.13143999874591827" iyz="0.0" izz="0.13143999874591827"/>
    </inertial>
  </link>
  <joint name="base_link_joint" type="fixed">
    <origin rpy="0 0 0" xyz="0 0 0"/>
    <parent link="body"/>
    <child link="base_link"/>
  </joint>
  <link name="front_rail">
    <inertial>
      <origin rpy="0. 0. 0." xyz="0. 0. 0."/>
      <mass value="1.0e-6"/>
      <inertia ixx="1.0e-9" ixy="0.0" ixz="0.0" iyy="1.0e-9" iyz="0.0" izz="1.0e-9"/>
    </inertial>
  </link>
  <joint name="front_rail_joint" type="fixed">
    <origin rpy="0 0 0" xyz="0.223 0 0.0805"/>
    <parent link="body"/>
    <child link="front_rail"/>
  </joint>
  <link name="rear_rail">
    <inertial>
      <origin rpy="0. 0. 0." xyz="0. 0. 0."/>
      <mass value="1.0e-6"/>
      <inertia ixx="1.0e-9" ixy="0.0" ixz="0.0" iyy="1.0e-9" iyz="0.0" izz="1.0e-9"/>
    </inertial>
  </link>
  <joint name="rear_rail_joint" type="fixed">
    <origin rpy="0 0 0" xyz="-0.223 0 0.0805"/>
    <parent link="body"/>
    <child link="rear_rail"/>
  </joint>
  <link name="front_left_hip">
    <visual>
      <geometry>
        <mesh filename="package://spot_description/meshes/base/visual/front_left_hip.obj"/>
      </geometry>
    </visual>
    <inertial>
      <origin rpy="-0.716521349312305 0.02956473059648479 0.03655230014702582" xyz="-0.005374345928430557 0.012841847725212574 9.875232353806496e-05"/>
      <mass value="1.68"/>
      <inertia ixx="0.0021147398873455382" ixy="0.0" ixz="0.0" iyy="0.0018129577956607131" iyz="0.0" izz="0.002265435737304666"/>
    </inertial>
  </link>
  <joint name="front_left_hip_x" type="revolute">
    <origin rpy="0 0 0" xyz="0.29785 0.05500 0.00000"/>
    <axis xyz="1 0 0"/>
    <parent link="body"/>
    <child link="front_left_hip"/>
    <limit effort="1000" lower="-0.78539816339744827899" upper="0.78539816339744827899" velocity="1000.00"/>
  </joint>
  <link name="front_left_upper_leg">
    <visual>
      <geometry>
        <mesh filename="package://spot_description/meshes/base/visual/front_left_upper_leg.obj"/>
      </geometry>
    </visual>
    <collision>
      <geometry>
        <mesh filename="package://spot_description/meshes/base/collision/left_upper_leg_collision.obj"/>
      </geometry>
    </collision>
    <inertial>
      <origin rpy="-0.26437828203369795 -0.04853174570753804 0.024046963096353124" xyz="0.005142373498529196 -0.0024323679972440004 -0.12100915610790253"/>
      <mass value="2.34"/>
      <inertia ixx="0.02755964961185679" ixy="0.0" ixz="0.0" iyy="0.027354914287651046" iyz="0.0" izz="0.002848145546743553"/>
    </inertial>
  </link>
  <joint name="front_left_hip_y" type="revolute">
    <origin rpy="0 0 0" xyz="0.0 0.110945 0.0"/>
    <axis xyz="0 1 0"/>
    <parent link="front_left_hip"/>
    <child link="front_left_upper_leg"/>
    <limit effort="1000" lower="-0.89884456477707963539" upper="2.2951079663725435509" velocity="1000.00"/>
  </joint>
  <link name="front_left_lower_leg">
    <visual>
      <geometry>
        <mesh filename="package://spot_description/meshes/base/visual/front_left_lower_leg.obj"/>
      </geometry>
    </visual>
    <collision>
      <geometry>
        <mesh filename="package://spot_description/meshes/base/collision/left_lower_leg_collision.obj"/>
      </geometry>
    </collision>
    <collision>
      <origin rpy="0 0 0" xyz="0.0 0.0 -0.3365"/>
      <geometry>
        <sphere radius="0.036"/>
      </geometry>
    </collision>
    <inertial>
      <origin rpy="-0.007266925694167092 -0.009591807116834161 0.00035255970529224356" xyz="0.00225794012658298 4.607596201822162e-05 -0.1800822913646698"/>
      <mass value="0.35"/>
      <inertia ixx="0.003999022654901177" ixy="0.0" ixz="0.0" iyy="0.0040503157598010785" iyz="0.0" izz="0.0001493402097647426"/>
    </inertial>
  </link>
  <joint name="front_left_knee" type="revolute">
    <origin rpy="0 0 0" xyz="0.025 0.000 -0.3205"/>
    <axis xyz="0 1 0"/>
    <parent link="front_left_upper_leg"/>
    <child link="front_left_lower_leg"/>
    <limit effort="1000" lower="-2.7929" upper="-0.254801" velocity="1000.00"/>
  </joint>
  <link name="front_right_hip">
    <visual>
      <geometry>
        <mesh filename="package://spot_description/meshes/base/visual/front_right_hip.obj"/>
      </geometry>
    </visual>
    <inertial>
      <origin rpy="0.7165213493123055 -0.02956473059648479 0.03655230014702582" xyz="-0.005374345928430557 -0.012841847725212574 -9.875232353806496e-05"/>
      <mass value="1.68"/>
      <inertia ixx="0.0021147398873455382" ixy="0.0" ixz="0.0" iyy="0.0018129577956607131" iyz="0.0" izz="0.002265435737304666"/>
    </inertial>
  </link>
  <joint name="front_right_hip_x" type="revolute">
    <origin rpy="0 0 0" xyz="0.29785 -0.05500 0.00000"/>
    <axis xyz="1 0 0"/>
    <parent link="body"/>
    <child link="front_right_hip"/>
    <limit effort="1000" lower="-0.78539816339744827899" upper="0.78539816339744827899" velocity="1000.00"/>
  </joint>
  <link name="front_right_upper_leg">
    <visual>
      <geometry>
        <mesh filename="package://spot_description/meshes/base/visual/front_right_upper_leg.obj"/>
      </geometry>
    </visual>
    <collision>
      <geometry>
        <mesh filename="package://spot_description/meshes/base/collision/right_upper_leg_collision.obj"/>
      </geometry>
    </collision>
    <inertial>
      <origin rpy="0.2643905306958363 -0.04853174688302708 -0.024046943559834943" xyz="0.005142373498529196 0.0024323677644133568 -0.12100915610790253"/>
      <mass value="2.34"/>
      <inertia ixx="0.02755964678927691" ixy="0.0" ixz="0.0" iyy="0.02735491706466737" iyz="0.0" izz="0.0028481453594764797"/>
    </inertial>
  </link>
  <joint name="front_right_hip_y" type="revolute">
    <origin rpy="0 0 0" xyz="0.0 -0.110945 0.0"/>
    <axis xyz="0 1 0"/>
    <parent link="front_right_hip"/>
    <child link="front_right_upper_leg"/>
    <limit effort="1000" lower="-0.89884456477707963539" upper="2.2951079663725435509" velocity="1000.00"/>
  </joint>
  <link name="front_right_lower_leg">
    <visual>
      <geometry>
        <mesh filename="package://spot_description/meshes/base/visual/front_right_lower_leg.obj"/>
      </geometry>
    </visual>
    <collision>
      <geometry>
        <mesh filename="package://spot_description/meshes/base/collision/right_lower_leg_collision.obj"/>
      </geometry>
    </collision>
    <collision>
      <origin rpy="0 0 0" xyz="0.0 0.0 -0.3365"/>
      <geometry>
        <sphere radius="0.036"/>
      </geometry>
    </collision>
    <inertial>
      <origin rpy="-0.007266925694167092 -0.009591807116834161 0.00035255970529224356" xyz="0.00225794012658298 4.607596201822162e-05 -0.1800822913646698"/>
      <mass value="0.35"/>
      <inertia ixx="0.003999022654901177" ixy="0.0" ixz="0.0" iyy="0.0040503157598010785" iyz="0.0" izz="0.0001493402097647426"/>
    </inertial>
  </link>
  <joint name="front_right_knee" type="revolute">
    <origin rpy="0 0 0" xyz="0.025 0.000 -0.3205"/>
    <axis xyz="0 1 0"/>
    <parent link="front_right_upper_leg"/>
    <child link="front_right_lower_leg"/>
    <limit effort="1000" lower="-2.7929" upper="-0.247563" velocity="1000.00"/>
  </joint>
  <link name="rear_left_hip">
    <visual>
      <geometry>
        <mesh filename="package://spot_description/meshes/base/visual/rear_left_hip.obj"/>
      </geometry>
    </visual>
    <inertial>
      <origin rpy="0.7165213493123055 -0.02956473059648479 0.03655230014702582" xyz="-0.005374345928430557 -0.012841847725212574 -9.875232353806496e-05"/>
      <mass value="1.68"/>
      <inertia ixx="0.0021147398873455382" ixy="0.0" ixz="0.0" iyy="0.0018129577956607131" iyz="0.0" izz="0.002265435737304666"/>
    </inertial>
  </link>
  <joint name="rear_left_hip_x" type="revolute">
    <origin rpy="0 0 0" xyz="-0.29785 0.05500 0.00000"/>
    <axis xyz="1 0 0"/>
    <parent link="body"/>
    <child link="rear_left_hip"/>
    <limit effort="1000" lower="-0.78539816339744827899" upper="0.78539816339744827899" velocity="1000.00"/>
  </joint>
  <link name="rear_left_upper_leg">
    <visual>
      <geometry>
        <mesh filename="package://spot_description/meshes/base/visual/rear_left_upper_leg.obj"/>
      </geometry>
    </visual>
    <collision>
      <geometry>
        <mesh filename="package://spot_description/meshes/base/collision/left_upper_leg_collision.obj"/>
      </geometry>
    </collision>
    <inertial>
      <origin rpy="-0.26437828203369795 -0.04853174570753804 0.024046963096353124" xyz="0.005142373498529196 -0.0024323679972440004 -0.12100915610790253"/>
      <mass value="2.34"/>
      <inertia ixx="0.02755964961185679" ixy="0.0" ixz="0.0" iyy="0.027354914287651046" iyz="0.0" izz="0.002848145546743553"/>
    </inertial>
  </link>
  <joint name="rear_left_hip_y" type="revolute">
    <origin rpy="0 0 0" xyz="0.0 0.110945 0.0"/>
    <axis xyz="0 1 0"/>
    <parent link="rear_left_hip"/>
    <child link="rear_left_upper_leg"/>
    <limit effort="1000" lower="-0.89884456477707963539" upper="2.2951079663725435509" velocity="1000.00"/>
  </joint>
  <link name="rear_left_lower_leg">
    <visual>
      <geometry>
        <mesh filename="package://spot_description/meshes/base/visual/rear_left_lower_leg.obj"/>
      </geometry>
    </visual>
    <collision>
      <geometry>
        <mesh filename="package://spot_description/meshes/base/collision/left_lower_leg_collision.obj"/>
      </geometry>
    </collision>
    <collision>
      <origin rpy="0 0 0" xyz="0.0 0.0 -0.3365"/>
      <geometry>
        <sphere radius="0.036"/>
      </geometry>
    </collision>
    <inertial>
      <origin rpy="-0.007266925694167092 -0.009591807116834161 0.00035255970529224356" xyz="0.00225794012658298 4.607596201822162e-05 -0.1800822913646698"/>
      <mass value="0.35"/>
      <inertia ixx="0.003999022654901177" ixy="0.0" ixz="0.0" iyy="0.0040503157598010785" iyz="0.0" izz="0.0001493402097647426"/>
    </inertial>
  </link>
  <joint name="rear_left_knee" type="revolute">
    <origin rpy="0 0 0" xyz="0.025 0.000 -0.3205"/>
    <axis xyz="0 1 0"/>
    <parent link="rear_left_upper_leg"/>
    <child link="rear_left_lower_leg"/>
    <limit effort="1000" lower="-2.7929" upper="-0.267153" velocity="1000.00"/>
  </joint>
  <link name="rear_right_hip">
    <visual>
      <geometry>
        <mesh filename="package://spot_description/meshes/base/visual/rear_right_hip.obj"/>
      </geometry>
    </visual>
    <inertial>
      <origin rpy="0.7165213493123055 -0.02956473059648479 0.03655230014702582" xyz="-0.005374345928430557 -0.012841847725212574 -9.875232353806496e-05"/>
      <mass value="1.68"/>
      <inertia ixx="0.0021147398873455382" ixy="0.0" ixz="0.0" iyy="0.0018129577956607131" iyz="0.0" izz="0.002265435737304666"/>
    </inertial>
  </link>
  <joint name="rear_right_hip_x" type="revolute">
    <origin rpy="0 0 0" xyz="-0.29785 -0.05500 0.00000"/>
    <axis xyz="1 0 0"/>
    <parent link="body"/>
    <child link="rear_right_hip"/>
    <limit effort="1000" lower="-0.78539816339744827899" upper="0.78539816339744827899" velocity="1000.00"/>
  </joint>
  <link name="rear_right_upper_leg">
    <visual>
      <geometry>
        <mesh filename="package://spot_description/meshes/base/visual/rear_right_upper_leg.obj"/>
      </geometry>
    </visual>
    <collision>
      <geometry>
        <mesh filename="package://spot_description/meshes/base/collision/right_upper_leg_collision.obj"/>
      </geometry>
    </collision>
    <inertial>
      <origin rpy="0.2643905306958363 -0.04853174688302708 -0.024046943559834943" xyz="0.005142373498529196 0.0024323677644133568 -0.12100915610790253"/>
      <mass value="2.34"/>
      <inertia ixx="0.02755964678927691" ixy="0.0" ixz="0.0" iyy="0.02735491706466737" iyz="0.0" izz="0.0028481453594764797"/>
    </inertial>
  </link>
  <joint name="rear_right_hip_y" type="revolute">
    <origin rpy="0 0 0" xyz="0.0 -0.110945 0.0"/>
    <axis xyz="0 1 0"/>
    <parent link="rear_right_hip"/>
    <child link="rear_right_upper_leg"/>
    <limit effort="1000" lower="-0.89884456477707963539" upper="2.2951079663725435509" velocity="1000.00"/>
  </joint>
  <link name="rear_right_lower_leg">
    <visual>
      <geometry>
        <mesh filename="package://spot_description/meshes/base/visual/rear_right_lower_leg.obj"/>
      </geometry>
    </visual>
    <collision>
      <geometry>
        <mesh filename="package://spot_description/meshes/base/collision/right_lower_leg_collision.obj"/>
      </geometry>
    </collision>
    <collision>
      <origin rpy="0 0 0" xyz="0.0 0.0 -0.3365"/>
      <geometry>
        <sphere radius="0.036"/>
      </geometry>
    </collision>
    <inertial>
      <origin rpy="-0.007266925694167092 -0.009591807116834161 0.00035255970529224356" xyz="0.00225794012658298 4.607596201822162e-05 -0.1800822913646698"/>
      <mass value="0.35"/>
      <inertia ixx="0.003999022654901177" ixy="0.0" ixz="0.0" iyy="0.0040503157598010785" iyz="0.0" izz="0.0001493402097647426"/>
    </inertial>
  </link>
  <joint name="rear_right_knee" type="revolute">
    <origin rpy="0 0 0" xyz="0.025 0.000 -0.3205"/>
    <axis xyz="0 1 0"/>
    <parent link="rear_right_upper_leg"/>
    <child link="rear_right_lower_leg"/>
    <limit effort="1000" lower="-2.7929" upper="-0.257725" velocity="1000.00"/>
  </joint>
  <drake:collision_filter_group name="group_front_right_upper_leg">
    <drake:member link="body"/>
    <drake:member link="front_right_upper_leg"/>
    <drake:ignored_collision_filter_group name="group_front_right_upper_leg"/>
  </drake:collision_filter_group>  
  <drake:collision_filter_group name="group_front_left_upper_leg">
    <drake:member link="body"/>
    <drake:member link="front_left_upper_leg"/>
    <drake:ignored_collision_filter_group name="group_front_left_upper_leg"/>
  </drake:collision_filter_group>
  <drake:collision_filter_group name="group_rear_left_upper_leg">
    <drake:member link="body"/>
    <drake:member link="rear_left_upper_leg"/>
    <drake:ignored_collision_filter_group name="group_rear_left_upper_leg"/>
  </drake:collision_filter_group>
  <drake:collision_filter_group name="group_rear_right_upper_leg">
    <drake:member link="body"/>
    <drake:member link="rear_right_upper_leg"/>
    <drake:ignored_collision_filter_group name="group_rear_right_upper_leg"/>
  </drake:collision_filter_group>
  <transmission type="SimpleTransmission" name="front_left_hip_x_trans">
    <actuator name="front_left_hip_x"/>
    <joint name="front_left_hip_x"/>
  </transmission>
  <transmission type="SimpleTransmission" name="front_left_hip_y_trans">
    <actuator name="front_left_hip_y"/>
    <joint name="front_left_hip_y"/>
  </transmission>
  <transmission type="SimpleTransmission" name="front_left_knee_trans">
    <actuator name="front_left_knee"/>
    <joint name="front_left_knee"/>
  </transmission>
  <transmission type="SimpleTransmission" name="front_right_hip_x_trans">
    <actuator name="front_right_hip_x"/>
    <joint name="front_right_hip_x"/>
  </transmission>
  <transmission type="SimpleTransmission" name="front_right_hip_y_trans">
    <actuator name="front_right_hip_y"/>
    <joint name="front_right_hip_y"/>
  </transmission>
  <transmission type="SimpleTransmission" name="front_right_knee_trans">
    <actuator name="front_right_knee"/>
    <joint name="front_right_knee"/>
  </transmission>
  <transmission type="SimpleTransmission" name="rear_left_hip_x_trans">
    <actuator name="rear_left_hip_x"/>
    <joint name="rear_left_hip_x"/>
  </transmission>
  <transmission type="SimpleTransmission" name="rear_left_hip_y_trans">
    <actuator name="rear_left_hip_y"/>
    <joint name="rear_left_hip_y"/>
  </transmission>
  <transmission type="SimpleTransmission" name="rear_left_knee_trans">
    <actuator name="rear_left_knee"/>
    <joint name="rear_left_knee"/>
  </transmission>
  <transmission type="SimpleTransmission" name="rear_right_hip_x_trans">
    <actuator name="rear_right_hip_x"/>
    <joint name="rear_right_hip_x"/>
  </transmission>
  <transmission type="SimpleTransmission" name="rear_right_hip_y_trans">
    <actuator name="rear_right_hip_y"/>
    <joint name="rear_right_hip_y"/>
  </transmission>
  <transmission type="SimpleTransmission" name="rear_right_knee_trans">
    <actuator name="rear_right_knee"/>
    <joint name="rear_right_knee"/>
  </transmission>
</robot>
